[2021-12-02 23:31:06,255] {taskinstance.py:670} INFO - Dependencies all met for <TaskInstance: twitter_dag.twitter_aluraonline 2021-11-24T09:00:00+00:00 [queued]>
[2021-12-02 23:31:06,260] {taskinstance.py:670} INFO - Dependencies all met for <TaskInstance: twitter_dag.twitter_aluraonline 2021-11-24T09:00:00+00:00 [queued]>
[2021-12-02 23:31:06,260] {taskinstance.py:880} INFO - 
--------------------------------------------------------------------------------
[2021-12-02 23:31:06,260] {taskinstance.py:881} INFO - Starting attempt 2 of 2
[2021-12-02 23:31:06,260] {taskinstance.py:882} INFO - 
--------------------------------------------------------------------------------
[2021-12-02 23:31:06,266] {taskinstance.py:901} INFO - Executing <Task(TwitterOperator): twitter_aluraonline> on 2021-11-24T09:00:00+00:00
[2021-12-02 23:31:06,267] {standard_task_runner.py:54} INFO - Started process 14569 to run task
[2021-12-02 23:31:06,313] {standard_task_runner.py:77} INFO - Running: ['airflow', 'run', 'twitter_dag', 'twitter_aluraonline', '2021-11-24T09:00:00+00:00', '--job_id', '61', '--pool', 'default_pool', '--raw', '-sd', 'DAGS_FOLDER/twitter_dag.py', '--cfg_path', '/tmp/tmpdgqmu6uh']
[2021-12-02 23:31:06,313] {standard_task_runner.py:78} INFO - Job 61: Subtask twitter_aluraonline
[2021-12-02 23:31:06,331] {logging_mixin.py:112} INFO - Running <TaskInstance: twitter_dag.twitter_aluraonline 2021-11-24T09:00:00+00:00 [running]> on host kauai-VirtualBox
[2021-12-02 23:31:06,370] {base_hook.py:89} INFO - Using connection to: id: twitter_default. Host: https://api.twitter.com, Port: None, Schema: None, Login: None, Password: None, extra: XXXXXXXX
[2021-12-02 23:31:06,372] {twitter_hook.py:36} INFO - URL: https://api.twitter.com/2/tweets/search/recent?query=AluraOnline&tweet.fields=author_id,conversation_id,created_at,id,in_reply_to_user_id,public_metrics,text&expansions=author_id&user.fields=id,name,username,created_at&start_time=2021-11-24T09:00:00.00Z&end_time=2021-11-25T09:00:00.00Z
[2021-12-02 23:31:06,617] {logging_mixin.py:112} WARNING - /home/kauai/datapipeline/venv/lib/python3.8/site-packages/urllib3/connectionpool.py:981: InsecureRequestWarning: Unverified HTTPS request is being made to host 'api.twitter.com'. Adding certificate verification is strongly advised. See: https://urllib3.readthedocs.io/en/latest/advanced-usage.html#ssl-warnings
  warnings.warn(
[2021-12-02 23:31:06,888] {http_hook.py:150} ERROR - HTTP error: Bad Request
[2021-12-02 23:31:06,888] {http_hook.py:151} ERROR - {"errors":[{"parameters":{"start_time":["2021-11-24T09:00Z"]},"message":"Invalid 'start_time':'2021-11-24T09:00Z'. 'start_time' must be on or after 2021-11-26T02:30Z"},{"parameters":{"end_time":["2021-11-25T09:00Z"]},"message":"Invalid 'end_time':'2021-11-25T09:00Z'. 'end_time' must be on or after 2021-11-26T02:30Z"}],"title":"Invalid Request","detail":"One or more parameters to your request was invalid.","type":"https://api.twitter.com/2/problems/invalid-request"}
[2021-12-02 23:31:06,890] {taskinstance.py:1150} ERROR - 400:Bad Request
Traceback (most recent call last):
  File "/home/kauai/datapipeline/venv/lib/python3.8/site-packages/airflow/hooks/http_hook.py", line 148, in check_response
    response.raise_for_status()
  File "/home/kauai/datapipeline/venv/lib/python3.8/site-packages/requests/models.py", line 941, in raise_for_status
    raise HTTPError(http_error_msg, response=self)
requests.exceptions.HTTPError: 400 Client Error: Bad Request for url: https://api.twitter.com/2/tweets/search/recent?query=AluraOnline&tweet.fields=author_id,conversation_id,created_at,id,in_reply_to_user_id,public_metrics,text&expansions=author_id&user.fields=id,name,username,created_at&start_time=2021-11-24T09:00:00.00Z&end_time=2021-11-25T09:00:00.00Z

During handling of the above exception, another exception occurred:

Traceback (most recent call last):
  File "/home/kauai/datapipeline/venv/lib/python3.8/site-packages/airflow/models/taskinstance.py", line 984, in _run_raw_task
    result = task_copy.execute(context=context)
  File "/home/kauai/airflow/plugins/operators/twitter_operator.py", line 49, in execute
    for pg in hook.run():
  File "/home/kauai/airflow/plugins/hooks/twitter_hook.py", line 56, in run
    yield from self.paginate(url, session)
  File "/home/kauai/airflow/plugins/hooks/twitter_hook.py", line 45, in paginate
    data = self.connect_to_endpoint(full_url, session)
  File "/home/kauai/airflow/plugins/hooks/twitter_hook.py", line 37, in connect_to_endpoint
    return self.run_and_check(session, prep, {}).json()
  File "/home/kauai/datapipeline/venv/lib/python3.8/site-packages/airflow/hooks/http_hook.py", line 181, in run_and_check
    self.check_response(response)
  File "/home/kauai/datapipeline/venv/lib/python3.8/site-packages/airflow/hooks/http_hook.py", line 152, in check_response
    raise AirflowException(str(response.status_code) + ":" + response.reason)
airflow.exceptions.AirflowException: 400:Bad Request
[2021-12-02 23:31:06,903] {taskinstance.py:1187} INFO - Marking task as FAILED. dag_id=twitter_dag, task_id=twitter_aluraonline, execution_date=20211124T090000, start_date=20211203T023106, end_date=20211203T023106
[2021-12-02 23:31:11,245] {local_task_job.py:102} INFO - Task exited with return code 1
